Workbook
Name 周: #REF!

Sheet Sheet1
A1: ="O2O业务日报"&TEXT(U1,"（m月d日）") -> O2O业务日报（3月25日） | T1: 日期 | U1: =[1]日报透视!B2 -> 2026-03-25 | V1: =GETPIVOTDATA("求和项:天数",[1]日报透视!$A$5) -> 1 | W1: =ROUND(V1,0) -> 1
A2: 东海店、文灶店、华信美团店缺失麦芽田数据
A3: 平台 | B3: 店铺 | C3: 实收金额 （含包装费/区域补贴） | D3: 招商货品成本合计 | E3: 总部招商利润 （不含房租人工） | F3: 单均运费 | G3: 日报运费 | H3: 平台/支付服务费 | I3: 订单距离 | J3: 票数 | K3: 平均订单距离 | L3: 店租金/人工预估 | M3: 推广费 | N3: 利润 | O3: 类型 | P3: 合计利润 （扣除房租人工） | T3: 辅助列房租水电 | U3: 推广费 | V3: 票数
A4: 饿了么 | B4: 余杭店 | C4: =SUMIFS([1]日报透视!E:E,[1]日报透视!A:A,A4,[1]日报透视!B:B,B4) -> 1392.51 | D4: =SUMIFS([1]日报透视!F:F,[1]日报透视!A:A,A4,[1]日报透视!B:B,B4) -> 883.33557 | E4: =SUMIFS([1]日报透视!G:G,[1]日报透视!A:A,A4,[1]日报透视!B:B,B4)-M4 -> 397.19443 | F4: =IFERROR(G4/J4,0) -> 6.2425 | G4: =SUMIFS([1]日报透视!I:I,[1]日报透视!A:A,A4,[1]日报透视!B:B,B4) -> 499.4 | H4: =SUMIFS([1]日报透视!J:J,[1]日报透视!A:A,A4,[1]日报透视!B:B,B4) -> 78.51 | I4: =SUMIFS([1]日报透视!K:K,[1]日报透视!A:A,A4,[1]日报透视!B:B,B4) -> 411.953 | J4: =SUMIFS([1]日报透视!L:L,[1]日报透视!A:A,A4,[1]日报透视!B:B,B4) -> 80 | K4: =IFERROR(I4/J4,0) -> 5.1494125 | L4: =T4 -> 273.05526 | M4: =SUMIFS([1]日报透视!N:N,[1]日报透视!A:A,A4,[1]日报透视!B:B,B4) -> 111.98 | N4: =E4-L4 -> 124.13917 | O4: =VLOOKUP(B4,[1]门店ID对应关系!J:K,2,0) -> 自营 | P4: =SUM($N$4:$N$42) -> 1482.8136 | Q4: =B4 -> 余杭店 | R4: =VLOOKUP(Q4,$B$4:$B$42,1,0) -> 余杭店 | T4: =VLOOKUP(B4,[1]房租水电人工成本!A:N,14,0)*V4*$W$1 -> 273.05526 | U4: =SUMIFS([1]饿了么推广费!W:W,[1]饿了么推广费!V:V,$U$1,[1]饿了么推广费!U:U,B4) -> 111.98 | V4: =IFERROR(J4/SUMIF(B:B,B4,J:J),0.25) -> 0.59259259 | W4: =IFERROR(U4*V4,0.25) -> 66.358519
A5: 饿了么 | B5: 首南店 | C5: =SUMIFS([1]日报透视!E:E,[1]日报透视!A:A,A5,[1]日报透视!B:B,B5) -> 1099.99 | D5: =SUMIFS([1]日报透视!F:F,[1]日报透视!A:A,A5,[1]日报透视!B:B,B5) -> 638.93267 | E5: =SUMIFS([1]日报透视!G:G,[1]日报透视!A:A,A5,[1]日报透视!B:B,B5)-M5 -> 381.97733 | F5: =IFERROR(G5/J5,0) -> 4.8147059 | G5: =SUMIFS([1]日报透视!I:I,[1]日报透视!A:A,A5,[1]日报透视!B:B,B5) -> 327.4 | H5: =SUMIFS([1]日报透视!J:J,[1]日报透视!A:A,A5,[1]日报透视!B:B,B5) -> 59.72 | I5: =SUMIFS([1]日报透视!K:K,[1]日报透视!A:A,A5,[1]日报透视!B:B,B5) -> 237.639 | J5: =SUMIFS([1]日报透视!L:L,[1]日报透视!A:A,A5,[1]日报透视!B:B,B5) -> 68 | K5: =IFERROR(I5/J5,0) -> 3.4946912 | L5: =T5 -> 249.88768 | M5: =SUMIFS([1]日报透视!N:N,[1]日报透视!A:A,A5,[1]日报透视!B:B,B5) -> 79.08 | N5: =E5-L5 -> 132.08965 | O5: =VLOOKUP(B5,[1]门店ID对应关系!J:K,2,0) -> 自营 | Q5: =B5 -> 首南店 | R5: =VLOOKUP(Q5,$B$4:$B$42,1,0) -> 首南店 | T5: =VLOOKUP(B5,[1]房租水电人工成本!A:N,14,0)*V5*$W$1 -> 249.88768 | U5: =SUMIFS([1]饿了么推广费!W:W,[1]饿了么推广费!V:V,$U$1,[1]饿了么推广费!U:U,B5) -> 79.08 | V5: =IFERROR(J5/SUMIF(B:B,B5,J:J),0.25) -> 0.45945946 | W5: =IFERROR(U5*V5,0.25) -> 36.334054
A6: 饿了么 | B6: 首山店 | C6: =SUMIFS([1]日报透视!E:E,[1]日报透视!A:A,A6,[1]日报透视!B:B,B6) -> 703.88 | D6: =SUMIFS([1]日报透视!F:F,[1]日报透视!A:A,A6,[1]日报透视!B:B,B6) -> 350.11667 | E6: =SUMIFS([1]日报透视!G:G,[1]日报透视!A:A,A6,[1]日报透视!B:B,B6)-M6 -> 300.11333 | F6: =IFERROR(G6/J6,0) -> 3.7618182 | G6: =SUMIFS([1]日报透视!I:I,[1]日报透视!A:A,A6,[1]日报透视!B:B,B6) -> 206.9 | H6: =SUMIFS([1]日报透视!J:J,[1]日报透视!A:A,A6,[1]日报透视!B:B,B6) -> 36.97 | I6: =SUMIFS([1]日报透视!K:K,[1]日报透视!A:A,A6,[1]日报透视!B:B,B6) -> 232.726 | J6: =SUMIFS([1]日报透视!L:L,[1]日报透视!A:A,A6,[1]日报透视!B:B,B6) -> 55 | K6: =IFERROR(I6/J6,0) -> 4.2313818 | L6: =T6 -> 289.71727 | M6: =SUMIFS([1]日报透视!N:N,[1]日报透视!A:A,A6,[1]日报透视!B:B,B6) -> 53.65 | N6: =E6-L6 -> 10.396061 | O6: =VLOOKUP(B6,[1]门店ID对应关系!J:K,2,0) -> 自营 | Q6: =B6 -> 首山店 | R6: =VLOOKUP(Q6,$B$4:$B$42,1,0) -> 首山店 | T6: =VLOOKUP(B6,[1]房租水电人工成本!A:N,14,0)*V6*$W$1 -> 289.71727 | U6: =SUMIFS([1]饿了么推广费!W:W,[1]饿了么推广费!V:V,$U$1,[1]饿了么推广费!U:U,B6) -> 53.65 | V6: =IFERROR(J6/SUMIF(B:B,B6,J:J),0.25) -> 0.45454545 | W6: =IFERROR(U6*V6,0.25) -> 24.386364
A7: 饿了么 | B7: 泉秀店 | C7: =SUMIFS([1]日报透视!E:E,[1]日报透视!A:A,A7,[1]日报透视!B:B,B7) -> 312.82 | D7: =SUMIFS([1]日报透视!F:F,[1]日报透视!A:A,A7,[1]日报透视!B:B,B7) -> 152.249 | E7: =SUMIFS([1]日报透视!G:G,[1]日报透视!A:A,A7,[1]日报透视!B:B,B7)-M7 -> 136.931 | F7: =IFERROR(G7/J7,0) -> 3.2055556 | G7: =SUMIFS([1]日报透视!I:I,[1]日报透视!A:A,A7,[1]日报透视!B:B,B7) -> 57.7 | H7: =SUMIFS([1]日报透视!J:J,[1]日报透视!A:A,A7,[1]日报透视!B:B,B7) -> 14.86 | I7: =SUMIFS([1]日报透视!K:K,[1]日报透视!A:A,A7,[1]日报透视!B:B,B7) -> 52.713 | J7: =SUMIFS([1]日报透视!L:L,[1]日报透视!A:A,A7,[1]日报透视!B:B,B7) -> 18 | K7: =IFERROR(I7/J7,0) -> 2.9285 | L7: =T7 -> 130.91111 | M7: =SUMIFS([1]日报透视!N:N,[1]日报透视!A:A,A7,[1]日报透视!B:B,B7) -> 23.64 | N7: =E7-L7 -> 6.0198889 | O7: =VLOOKUP(B7,[1]门店ID对应关系!J:K,2,0) -> 自营 | Q7: =B7 -> 泉秀店 | R7: =VLOOKUP(Q7,$B$4:$B$42,1,0) -> 泉秀店 | T7: =VLOOKUP(B7,[1]房租水电人工成本!A:N,14,0)*V7*$W$1 -> 130.91111 | U7: =SUMIFS([1]饿了么推广费!W:W,[1]饿了么推广费!V:V,$U$1,[1]饿了么推广费!U:U,B7) -> 23.64 | V7: =IFERROR(J7/SUMIF(B:B,B7,J:J),0.25) -> 0.4 | W7: =IFERROR(U7*V7,0.25) -> 9.456
A8: 饿了么 | B8: 诚毅店 | C8: =SUMIFS([1]日报透视!E:E,[1]日报透视!A:A,A8,[1]日报透视!B:B,B8) -> 849.81 | D8: =SUMIFS([1]日报透视!F:F,[1]日报透视!A:A,A8,[1]日报透视!B:B,B8) -> 490.16567 | E8: =SUMIFS([1]日报透视!G:G,[1]日报透视!A:A,A8,[1]日报透视!B:B,B8)-M8 -> 294.71433 | F8: =IFERROR(G8/J8,0) -> 5.3358974 | G8: =SUMIFS([1]日报透视!I:I,[1]日报透视!A:A,A8,[1]日报透视!B:B,B8) -> 208.1 | H8: =SUMIFS([1]日报透视!J:J,[1]日报透视!A:A,A8,[1]日报透视!B:B,B8) -> 43.09 | I8: =SUMIFS([1]日报透视!K:K,[1]日报透视!A:A,A8,[1]日报透视!B:B,B8) -> 181.11 | J8: =SUMIFS([1]日报透视!L:L,[1]日报透视!A:A,A8,[1]日报透视!B:B,B8) -> 39 | K8: =IFERROR(I8/J8,0) -> 4.6438462 | L8: =T8 -> 166.29283 | M8: =SUMIFS([1]日报透视!N:N,[1]日报透视!A:A,A8,[1]日报透视!B:B,B8) -> 64.93 | N8: =E8-L8 -> 128.4215 | O8: =VLOOKUP(B8,[1]门店ID对应关系!J:K,2,0) -> 自营 | Q8: =B8 -> 诚毅店 | R8: =VLOOKUP(Q8,$B$4:$B$42,1,0) -> 诚毅店 | T8: =VLOOKUP(B8,[1]房租水电人工成本!A:N,14,0)*V8*$W$1 -> 166.29283 | U8: =SUMIFS([1]饿了么推广费!W:W,[1]饿了么推广费!V:V,$U$1,[1]饿了么推广费!U:U,B8) -> 64.93 | V8: =IFERROR(J8/SUMIF(B:B,B8,J:J),0.25) -> 0.38235294 | W8: =IFERROR(U8*V8,0.25) -> 24.826176
A9: 饿了么 | B9: 武侯店 | C9: =SUMIFS([1]日报透视!E:E,[1]日报透视!A:A,A9,[1]日报透视!B:B,B9) -> 521.59 | D9: =SUMIFS([1]日报透视!F:F,[1]日报透视!A:A,A9,[1]日报透视!B:B,B9) -> 295.4756 | E9: =SUMIFS([1]日报透视!G:G,[1]日报透视!A:A,A9,[1]日报透视!B:B,B9)-M9 -> 181.0744 | F9: =IFERROR(G9/J9,0) -> 4.4805556 | G9: =SUMIFS([1]日报透视!I:I,[1]日报透视!A:A,A9,[1]日报透视!B:B,B9) -> 161.3 | H9: =SUMIFS([1]日报透视!J:J,[1]日报透视!A:A,A9,[1]日报透视!B:B,B9) -> 27.34 | I9: =SUMIFS([1]日报透视!K:K,[1]日报透视!A:A,A9,[1]日报透视!B:B,B9) -> 148.482 | J9: =SUMIFS([1]日报透视!L:L,[1]日报透视!A:A,A9,[1]日报透视!B:B,B9) -> 36 | K9: =IFERROR(I9/J9,0) -> 4.1245 | L9: =T9 -> 209.11604 | M9: =SUMIFS([1]日报透视!N:N,[1]日报透视!A:A,A9,[1]日报透视!B:B,B9) -> 45.04 | N9: =E9-L9 -> -28.041639 | O9: =VLOOKUP(B9,[1]门店ID对应关系!J:K,2,0) -> 自营 | Q9: =B9 -> 武侯店 | R9: =VLOOKUP(Q9,$B$4:$B$42,1,0) -> 武侯店 | T9: =VLOOKUP(B9,[1]房租水电人工成本!A:N,14,0)*V9*$W$1 -> 209.11604 | U9: =SUMIFS([1]饿了么推广费!W:W,[1]饿了么推广费!V:V,$U$1,[1]饿了么推广费!U:U,B9) -> 45.04 | V9: =IFERROR(J9/SUMIF(B:B,B9,J:J),0.25) -> 0.42352941 | W9: =IFERROR(U9*V9,0.25) -> 19.075765
A10: 饿了么 | B10: 湖里店 | C10: =SUMIFS([1]日报透视!E:E,[1]日报透视!A:A,A10,[1]日报透视!B:B,B10) -> 1606.07 | D10: =SUMIFS([1]日报透视!F:F,[1]日报透视!A:A,A10,[1]日报透视!B:B,B10) -> 1015.179 | E10: =SUMIFS([1]日报透视!G:G,[1]日报透视!A:A,A10,[1]日报透视!B:B,B10)-M10 -> 464.111 | F10: =IFERROR(G10/J10,0) -> 5.4506494 | G10: =SUMIFS([1]日报透视!I:I,[1]日报透视!A:A,A10,[1]日报透视!B:B,B10) -> 419.7 | H10: =SUMIFS([1]日报透视!J:J,[1]日报透视!A:A,A10,[1]日报透视!B:B,B10) -> 81.18 | I10: =SUMIFS([1]日报透视!K:K,[1]日报透视!A:A,A10,[1]日报透视!B:B,B10) -> 299.586 | J10: =SUMIFS([1]日报透视!L:L,[1]日报透视!A:A,A10,[1]日报透视!B:B,B10) -> 77 | K10: =IFERROR(I10/J10,0) -> 3.8907273 | L10: =T10 -> 316.74788 | M10: =SUMIFS([1]日报透视!N:N,[1]日报透视!A:A,A10,[1]日报透视!B:B,B10) -> 126.78 | N10: =E10-L10 -> 147.36312 | O10: =VLOOKUP(B10,[1]门店ID对应关系!J:K,2,0) -> 自营 | Q10: =B10 -> 湖里店 | R10: =VLOOKUP(Q10,$B$4:$B$42,1,0) -> 湖里店 | T10: =VLOOKUP(B10,[1]房租水电人工成本!A:N,14,0)*V10*$W$1 -> 316.74788 | U10: =SUMIFS([1]饿了么推广费!W:W,[1]饿了么推广费!V:V,$U$1,[1]饿了么推广费!U:U,B10) -> 126.78 | V10: =IFERROR(J10/SUMIF(B:B,B10,J:J),0.25) -> 0.59230769 | W10: =IFERROR(U10*V10,0.25) -> 75.092769
A11: 饿了么 | B11: 鼓楼店 | C11: =SUMIFS([1]日报透视!E:E,[1]日报透视!A:A,A11,[1]日报透视!B:B,B11) -> 2272.45 | D11: =SUMIFS([1]日报透视!F:F,[1]日报透视!A:A,A11,[1]日报透视!B:B,B11) -> 1542.8422 | E11: =SUMIFS([1]日报透视!G:G,[1]日报透视!A:A,A11,[1]日报透视!B:B,B11)-M11 -> 579.02775 | F11: =IFERROR(G11/J11,0) -> 4.8151515 | G11: =SUMIFS([1]日报透视!I:I,[1]日报透视!A:A,A11,[1]日报透视!B:B,B11) -> 317.8 | H11: =SUMIFS([1]日报透视!J:J,[1]日报透视!A:A,A11,[1]日报透视!B:B,B11) -> 113.79 | I11: =SUMIFS([1]日报透视!K:K,[1]日报透视!A:A,A11,[1]日报透视!B:B,B11) -> 282.811 | J11: =SUMIFS([1]日报透视!L:L,[1]日报透视!A:A,A11,[1]日报透视!B:B,B11) -> 66 | K11: =IFERROR(I11/J11,0) -> 4.2850152 | L11: =T11 -> 216.8101 | M11: =SUMIFS([1]日报透视!N:N,[1]日报透视!A:A,A11,[1]日报透视!B:B,B11) -> 150.58 | N11: =E11-L11 -> 362.21765 | O11: =VLOOKUP(B11,[1]门店ID对应关系!J:K,2,0) -> 自营 | Q11: =B11 -> 鼓楼店 | R11: =VLOOKUP(Q11,$B$4:$B$42,1,0) -> 鼓楼店 | T11: =VLOOKUP(B11,[1]房租水电人工成本!A:N,14,0)*V11*$W$1 -> 216.8101 | U11: =SUMIFS([1]饿了么推广费!W:W,[1]饿了么推广费!V:V,$U$1,[1]饿了么推广费!U:U,B11) -> 150.58 | V11: =IFERROR(J11/SUMIF(B:B,B11,J:J),0.25) -> 0.45833333 | W11: =IFERROR(U11*V11,0.25) -> 69.015833
A12: 饿了么 | B12: 百捷店 | C12: =SUMIFS([1]日报透视!E:E,[1]日报透视!A:A,A12,[1]日报透视!B:B,B12) -> 1025.05 | D12: =SUMIFS([1]日报透视!F:F,[1]日报透视!A:A,A12,[1]日报透视!B:B,B12) -> 559.35517 | E12: =SUMIFS([1]日报透视!G:G,[1]日报透视!A:A,A12,[1]日报透视!B:B,B12)-M12 -> 372.70483 | F12: =IFERROR(G12/J12,0) -> 4.4613115 | G12: =SUMIFS([1]日报透视!I:I,[1]日报透视!A:A,A12,[1]日报透视!B:B,B12) -> 272.14 | H12: =SUMIFS([1]日报透视!J:J,[1]日报透视!A:A,A12,[1]日报透视!B:B,B12) -> 52.24 | I12: =SUMIFS([1]日报透视!K:K,[1]日报透视!A:A,A12,[1]日报透视!B:B,B12) -> 242.253 | J12: =SUMIFS([1]日报透视!L:L,[1]日报透视!A:A,A12,[1]日报透视!B:B,B12) -> 61 | K12: =IFERROR(I12/J12,0) -> 3.9713607 | L12: =T12 -> 203.51985 | M12: =SUMIFS([1]日报透视!N:N,[1]日报透视!A:A,A12,[1]日报透视!B:B,B12) -> 77.15 | N12: =E12-L12 -> 169.18499 | O12: =VLOOKUP(B12,[1]门店ID对应关系!J:K,2,0) -> 自营 | Q12: =B12 -> 百捷店 | R12: =VLOOKUP(Q12,$B$4:$B$42,1,0) -> 百捷店 | T12: =VLOOKUP(B12,[1]房租水电人工成本!A:N,14,0)*V12*$W$1 -> 203.51985 | U12: =SUMIFS([1]饿了么推广费!W:W,[1]饿了么推广费!V:V,$U$1,[1]饿了么推广费!U:U,B12) -> 77.15 | V12: =IFERROR(J12/SUMIF(B:B,B12,J:J),0.25) -> 0.49593496 | W12: =IFERROR(U12*V12,0.25) -> 38.261382
A13: 饿了么 | B13: 济南店 | C13: =SUMIFS([1]日报透视!E:E,[1]日报透视!A:A,A13,[1]日报透视!B:B,B13) -> 1568.33 | D13: =SUMIFS([1]日报透视!F:F,[1]日报透视!A:A,A13,[1]日报透视!B:B,B13) -> 1004.6224 | E13: =SUMIFS([1]日报透视!G:G,[1]日报透视!A:A,A13,[1]日报透视!B:B,B13)-M13 -> 423.2876 | F13: =IFERROR(G13/J13,0) -> 5.1176471 | G13: =SUMIFS([1]日报透视!I:I,[1]日报透视!A:A,A13,[1]日报透视!B:B,B13) -> 348 | H13: =SUMIFS([1]日报透视!J:J,[1]日报透视!A:A,A13,[1]日报透视!B:B,B13) -> 91.32 | I13: =SUMIFS([1]日报透视!K:K,[1]日报透视!A:A,A13,[1]日报透视!B:B,B13) -> 249.36 | J13: =SUMIFS([1]日报透视!L:L,[1]日报透视!A:A,A13,[1]日报透视!B:B,B13) -> 68 | K13: =IFERROR(I13/J13,0) -> 3.6670588 | L13: =T13 -> 345.75725 | M13: =SUMIFS([1]日报透视!N:N,[1]日报透视!A:A,A13,[1]日报透视!B:B,B13) -> 118.82 | N13: =E13-L13 -> 77.530341 | O13: =VLOOKUP(B13,[1]门店ID对应关系!J:K,2,0) -> 自营 | Q13: =B13 -> 济南店 | R13: =VLOOKUP(Q13,$B$4:$B$42,1,0) -> 济南店 | T13: =VLOOKUP(B13,[1]房租水电人工成本!A:N,14,0)*V13*$W$1 -> 345.75725 | U13: =SUMIFS([1]饿了么推广费!W:W,[1]饿了么推广费!V:V,$U$1,[1]饿了么推广费!U:U,B13) -> 118.82 | V13: =IFERROR(J13/SUMIF(B:B,B13,J:J),0.25) -> 0.53543307 | W13: =IFERROR(U13*V13,0.25) -> 63.620157
A14: 饿了么 | B14: 高新店 | C14: =SUMIFS([1]日报透视!E:E,[1]日报透视!A:A,A14,[1]日报透视!B:B,B14) -> 1034.19 | D14: =SUMIFS([1]日报透视!F:F,[1]日报透视!A:A,A14,[1]日报透视!B:B,B14) -> 645.10667 | E14: =SUMIFS([1]日报透视!G:G,[1]日报透视!A:A,A14,[1]日报透视!B:B,B14)-M14 -> 326.61333 | F14: =IFERROR(G14/J14,0) -> 4.852381 | G14: =SUMIFS([1]日报透视!I:I,[1]日报透视!A:A,A14,[1]日报透视!B:B,B14) -> 203.8 | H14: =SUMIFS([1]日报透视!J:J,[1]日报透视!A:A,A14,[1]日报透视!B:B,B14) -> 49.92 | I14: =SUMIFS([1]日报透视!K:K,[1]日报透视!A:A,A14,[1]日报透视!B:B,B14) -> 183.592 | J14: =SUMIFS([1]日报透视!L:L,[1]日报透视!A:A,A14,[1]日报透视!B:B,B14) -> 42 | K14: =IFERROR(I14/J14,0) -> 4.3712381 | L14: =T14 -> 226.00193 | M14: =SUMIFS([1]日报透视!N:N,[1]日报透视!A:A,A14,[1]日报透视!B:B,B14) -> 62.47 | N14: =E14-L14 -> 100.6114 | O14: =VLOOKUP(B14,[1]门店ID对应关系!J:K,2,0) -> 自营 | Q14: =B14 -> 高新店 | R14: =VLOOKUP(Q14,$B$4:$B$42,1,0) -> 高新店 | T14: =VLOOKUP(B14,[1]房租水电人工成本!A:N,14,0)*V14*$W$1 -> 226.00193 | U14: =SUMIFS([1]饿了么推广费!W:W,[1]饿了么推广费!V:V,$U$1,[1]饿了么推广费!U:U,B14) -> 62.47 | V14: =IFERROR(J14/SUMIF(B:B,B14,J:J),0.25) -> 0.4516129 | W14: =IFERROR(U14*V14,0.25) -> 28.212258
A15: 饿了么 | B15: 五华店 | C15: =SUMIFS([1]日报透视!E:E,[1]日报透视!A:A,A15,[1]日报透视!B:B,B15) -> 594.81 | D15: =SUMIFS([1]日报透视!F:F,[1]日报透视!A:A,A15,[1]日报透视!B:B,B15) -> 300.70136 | E15: =SUMIFS([1]日报透视!G:G,[1]日报透视!A:A,A15,[1]日报透视!B:B,B15)-M15 -> 259.65864 | F15: =IFERROR(G15/J15,0) -> 3.7361111 | G15: =SUMIFS([1]日报透视!I:I,[1]日报透视!A:A,A15,[1]日报透视!B:B,B15) -> 134.5 | H15: =SUMIFS([1]日报透视!J:J,[1]日报透视!A:A,A15,[1]日报透视!B:B,B15) -> 29.2 | I15: =SUMIFS([1]日报透视!K:K,[1]日报透视!A:A,A15,[1]日报透视!B:B,B15) -> 107.784 | J15: =SUMIFS([1]日报透视!L:L,[1]日报透视!A:A,A15,[1]日报透视!B:B,B15) -> 36 | K15: =IFERROR(I15/J15,0) -> 2.994 | L15: =T15 -> 125.3612 | M15: =SUMIFS([1]日报透视!N:N,[1]日报透视!A:A,A15,[1]日报透视!B:B,B15) -> 34.45 | N15: =E15-L15 -> 134.29744 | O15: =VLOOKUP(B15,[1]门店ID对应关系!J:K,2,0) -> 自营 | Q15: =B15 -> 五华店 | R15: =VLOOKUP(Q15,$B$4:$B$42,1,0) -> 五华店 | T15: =VLOOKUP(B15,[1]房租水电人工成本!A:N,14,0)*V15*$W$1 -> 125.3612 | U15: =SUMIFS([1]饿了么推广费!W:W,[1]饿了么推广费!V:V,$U$1,[1]饿了么推广费!U:U,B15) -> 34.45 | V15: =IFERROR(J15/SUMIF(B:B,B15,J:J),0.25) -> 0.36363636 | W15: =IFERROR(U15*V15,0.25) -> 12.527273
A16: 饿了么 | B16: 东新店 | C16: =SUMIFS([1]日报透视!E:E,[1]日报透视!A:A,A16,[1]日报透视!B:B,B16) -> 921.77 | D16: =SUMIFS([1]日报透视!F:F,[1]日报透视!A:A,A16,[1]日报透视!B:B,B16) -> 531.92106 | E16: =SUMIFS([1]日报透视!G:G,[1]日报透视!A:A,A16,[1]日报透视!B:B,B16)-M16 -> 351.55894 | F16: =IFERROR(G16/J16,0) -> 5.5491525 | G16: =SUMIFS([1]日报透视!I:I,[1]日报透视!A:A,A16,[1]日报透视!B:B,B16) -> 327.4 | H16: =SUMIFS([1]日报透视!J:J,[1]日报透视!A:A,A16,[1]日报透视!B:B,B16) -> 54.83 | I16: =SUMIFS([1]日报透视!K:K,[1]日报透视!A:A,A16,[1]日报透视!B:B,B16) -> 183.37 | J16: =SUMIFS([1]日报透视!L:L,[1]日报透视!A:A,A16,[1]日报透视!B:B,B16) -> 59 | K16: =IFERROR(I16/J16,0) -> 3.1079661 | L16: =T16 -> 175.5098 | M16: =SUMIFS([1]日报透视!N:N,[1]日报透视!A:A,A16,[1]日报透视!B:B,B16) -> 38.29 | N16: =E16-L16 -> 176.04914 | O16: =VLOOKUP(B16,[1]门店ID对应关系!J:K,2,0) -> 自营 | Q16: =B16 -> 东新店 | R16: =VLOOKUP(Q16,$B$4:$B$42,1,0) -> 东新店 | T16: =VLOOKUP(B16,[1]房租水电人工成本!A:N,14,0)*V16*$W$1 -> 175.5098 | U16: =SUMIFS([1]饿了么推广费!W:W,[1]饿了么推广费!V:V,$U$1,[1]饿了么推广费!U:U,B16) -> 38.29 | V16: =IFERROR(J16/SUMIF(B:B,B16,J:J),0.25) -> 0.38064516 | W16: =IFERROR(U16*V16,0.25) -> 14.574903
... A42: 饿了么 | B42: 南安店 | C42: =SUMIFS([1]日报透视!E:E,[1]日报透视!A:A,A42,[1]日报透视!B:B,B42) -> 503.36 | D42: =SUMIFS([1]日报透视!F:F,[1]日报透视!A:A,A42,[1]日报透视!B:B,B42) -> 266.35 | E42: =SUMIFS([1]日报透视!G:G,[1]日报透视!A:A,A42,[1]日报透视!B:B,B42)-M42 -> 206.29 | F42: =IFERROR(G42/J42,0) -> 6.2577778 | G42: =SUMIFS([1]日报透视!I:I,[1]日报透视!A:A,A42,[1]日报透视!B:B,B42) -> 56.32 | H42: =SUMIFS([1]日报透视!J:J,[1]日报透视!A:A,A42,[1]日报透视!B:B,B42) -> 37.54 | I42: =SUMIFS([1]日报透视!K:K,[1]日报透视!A:A,A42,[1]日报透视!B:B,B42) -> 37.92 | J42: =SUMIFS([1]日报透视!L:L,[1]日报透视!A:A,A42,[1]日报透视!B:B,B42) -> 9 | K42: =IFERROR(I42/J42,0) -> 4.2133333 | L42: =T42 -> 174.19355 | M42: =SUMIFS([1]日报透视!N:N,[1]日报透视!A:A,A42,[1]日报透视!B:B,B42) -> 19.4 | N42: =E42-L42 -> 32.096452 | O42: =VLOOKUP(B42,[1]门店ID对应关系!J:K,2,0) -> 加盟 | Q42: =B42 -> 南安店 | R42: =VLOOKUP(Q42,$B$4:$B$42,1,0) -> 南安店 | T42: =VLOOKUP(B42,[1]房租水电人工成本!A:N,14,0)*V42*$W$1 -> 174.19355 | U42: =SUMIFS([1]饿了么推广费!W:W,[1]饿了么推广费!V:V,$U$1,[1]饿了么推广费!U:U,B42) -> 19.4 | V42: =IFERROR(J42/SUMIF(B:B,B42,J:J),0.25) -> 0.29032258 | W42: =IFERROR(U42*V42,0.25) -> 5.6322581
A43: 京东 | B43: 余杭店 | C43: =SUMIFS([1]日报透视!E:E,[1]日报透视!A:A,A43,[1]日报透视!B:B,B43) -> 15.3 | D43: =SUMIFS([1]日报透视!F:F,[1]日报透视!A:A,A43,[1]日报透视!B:B,B43) -> 5.22 | E43: =SUMIFS([1]日报透视!G:G,[1]日报透视!A:A,A43,[1]日报透视!B:B,B43)-M43 -> 10.08 | F43: =IFERROR(G43/J43,0) -> 1.8 | G43: =SUMIFS([1]日报透视!I:I,[1]日报透视!A:A,A43,[1]日报透视!B:B,B43) -> 1.8 | H43: =SUMIFS([1]日报透视!J:J,[1]日报透视!A:A,A43,[1]日报透视!B:B,B43) -> 0.9 | I43: =SUMIFS([1]日报透视!K:K,[1]日报透视!A:A,A43,[1]日报透视!B:B,B43) -> 1.87 | J43: =SUMIFS([1]日报透视!L:L,[1]日报透视!A:A,A43,[1]日报透视!B:B,B43) -> 1 | K43: =IFERROR(I43/J43,0) -> 1.87 | L43: =T43 -> 3.4131907 | M43: =SUMIFS([1]日报透视!N:N,[1]日报透视!A:A,A43,[1]日报透视!B:B,B43) -> 0 | N43: =E43-L43 -> 6.6668093 | O43: =VLOOKUP(B43,[1]门店ID对应关系!J:K,2,0) -> 自营 | P43: =SUM($N$43:$N$81) -> 282.63834 | Q43: =B43 -> 余杭店 | R43: =VLOOKUP(Q43,$B$4:$B$42,1,0) -> 余杭店 | T43: =VLOOKUP(B43,[1]房租水电人工成本!A:N,14,0)*V43*$W$1 -> 3.4131907 | U43: 0 | V43: =IFERROR(J43/SUMIF(B:B,B43,J:J),0.25) -> 0.0074074074 | W43: =IFERROR(U43*V43,0.25) -> 0
A44: 京东 | B44: 济南店 | C44: =SUMIFS([1]日报透视!E:E,[1]日报透视!A:A,A44,[1]日报透视!B:B,B44) -> 0 | D44: =SUMIFS([1]日报透视!F:F,[1]日报透视!A:A,A44,[1]日报透视!B:B,B44) -> 0 | E44: =SUMIFS([1]日报透视!G:G,[1]日报透视!A:A,A44,[1]日报透视!B:B,B44)-M44 -> 0 | F44: =IFERROR(G44/J44,0) -> 0 | G44: =SUMIFS([1]日报透视!I:I,[1]日报透视!A:A,A44,[1]日报透视!B:B,B44) -> 0 | H44: =SUMIFS([1]日报透视!J:J,[1]日报透视!A:A,A44,[1]日报透视!B:B,B44) -> 0 | I44: =SUMIFS([1]日报透视!K:K,[1]日报透视!A:A,A44,[1]日报透视!B:B,B44) -> 0 | J44: =SUMIFS([1]日报透视!L:L,[1]日报透视!A:A,A44,[1]日报透视!B:B,B44) -> 0 | K44: =IFERROR(I44/J44,0) -> 0 | L44: =T44 -> 0 | M44: =SUMIFS([1]日报透视!N:N,[1]日报透视!A:A,A44,[1]日报透视!B:B,B44) -> 0 | N44: =E44-L44 -> 0 | O44: =VLOOKUP(B44,[1]门店ID对应关系!J:K,2,0) -> 自营 | Q44: =B44 -> 济南店 | R44: =VLOOKUP(Q44,$B$4:$B$42,1,0) -> 济南店 | T44: =VLOOKUP(B44,[1]房租水电人工成本!A:N,14,0)*V44*$W$1 -> 0 | U44: 0 | V44: =IFERROR(J44/SUMIF(B:B,B44,J:J),0.25) -> 0 | W44: =IFERROR(U44*V44,0.25) -> 0
A45: 京东 | B45: 青羊店 | C45: =SUMIFS([1]日报透视!E:E,[1]日报透视!A:A,A45,[1]日报透视!B:B,B45) -> 340 | D45: =SUMIFS([1]日报透视!F:F,[1]日报透视!A:A,A45,[1]日报透视!B:B,B45) -> 221 | E45: =SUMIFS([1]日报透视!G:G,[1]日报透视!A:A,A45,[1]日报透视!B:B,B45)-M45 -> 119 | F45: =IFERROR(G45/J45,0) -> 2 | G45: =SUMIFS([1]日报透视!I:I,[1]日报透视!A:A,A45,[1]日报透视!B:B,B45) -> 2 | H45: =SUMIFS([1]日报透视!J:J,[1]日报透视!A:A,A45,[1]日报透视!B:B,B45) -> 18 | I45: =SUMIFS([1]日报透视!K:K,[1]日报透视!A:A,A45,[1]日报透视!B:B,B45) -> 9.056 | J45: =SUMIFS([1]日报透视!L:L,[1]日报透视!A:A,A45,[1]日报透视!B:B,B45) -> 1 | K45: =IFERROR(I45/J45,0) -> 9.056 | L45: =T45 -> 7.547001 | M45: =SUMIFS([1]日报透视!N:N,[1]日报透视!A:A,A45,[1]日报透视!B:B,B45) -> 0 | N45: =E45-L45 -> 111.453 | O45: =VLOOKUP(B45,[1]门店ID对应关系!J:K,2,0) -> 自营 | Q45: =B45 -> 青羊店 | R45: =VLOOKUP(Q45,$B$4:$B$42,1,0) -> 青羊店 | T45: =VLOOKUP(B45,[1]房租水电人工成本!A:N,14,0)*V45*$W$1 -> 7.547001 | U45: 0 | V45: =IFERROR(J45/SUMIF(B:B,B45,J:J),0.25) -> 0.015873016 | W45: =IFERROR(U45*V45,0.25) -> 0
A46: 京东 | B46: 西湖店 | C46: =SUMIFS([1]日报透视!E:E,[1]日报透视!A:A,A46,[1]日报透视!B:B,B46) -> 0 | D46: =SUMIFS([1]日报透视!F:F,[1]日报透视!A:A,A46,[1]日报透视!B:B,B46) -> 0 | E46: =SUMIFS([1]日报透视!G:G,[1]日报透视!A:A,A46,[1]日报透视!B:B,B46)-M46 -> 0 | F46: =IFERROR(G46/J46,0) -> 0 | G46: =SUMIFS([1]日报透视!I:I,[1]日报透视!A:A,A46,[1]日报透视!B:B,B46) -> 0 | H46: =SUMIFS([1]日报透视!J:J,[1]日报透视!A:A,A46,[1]日报透视!B:B,B46) -> 0 | I46: =SUMIFS([1]日报透视!K:K,[1]日报透视!A:A,A46,[1]日报透视!B:B,B46) -> 0 | J46: =SUMIFS([1]日报透视!L:L,[1]日报透视!A:A,A46,[1]日报透视!B:B,B46) -> 0 | K46: =IFERROR(I46/J46,0) -> 0 | L46: =T46 -> 0 | M46: =SUMIFS([1]日报透视!N:N,[1]日报透视!A:A,A46,[1]日报透视!B:B,B46) -> 0 | N46: =E46-L46 -> 0 | O46: =VLOOKUP(B46,[1]门店ID对应关系!J:K,2,0) -> 自营 | Q46: =B46 -> 西湖店 | R46: =VLOOKUP(Q46,$B$4:$B$42,1,0) -> 西湖店 | T46: =VLOOKUP(B46,[1]房租水电人工成本!A:N,14,0)*V46*$W$1 -> 0 | U46: 0 | V46: =IFERROR(J46/SUMIF(B:B,B46,J:J),0.25) -> 0 | W46: =IFERROR(U46*V46,0.25) -> 0
A47: 京东 | B47: 大坪店 | C47: =SUMIFS([1]日报透视!E:E,[1]日报透视!A:A,A47,[1]日报透视!B:B,B47) -> 22.9 | D47: =SUMIFS([1]日报透视!F:F,[1]日报透视!A:A,A47,[1]日报透视!B:B,B47) -> 5.6 | E47: =SUMIFS([1]日报透视!G:G,[1]日报透视!A:A,A47,[1]日报透视!B:B,B47)-M47 -> 17.3 | F47: =IFERROR(G47/J47,0) -> 1.8 | G47: =SUMIFS([1]日报透视!I:I,[1]日报透视!A:A,A47,[1]日报透视!B:B,B47) -> 1.8 | H47: =SUMIFS([1]日报透视!J:J,[1]日报透视!A:A,A47,[1]日报透视!B:B,B47) -> 1.3 | I47: =SUMIFS([1]日报透视!K:K,[1]日报透视!A:A,A47,[1]日报透视!B:B,B47) -> 1.368 | J47: =SUMIFS([1]日报透视!L:L,[1]日报透视!A:A,A47,[1]日报透视!B:B,B47) -> 1 | K47: =IFERROR(I47/J47,0) -> 1.368 | L47: =T47 -> 4.4444725 | M47: =SUMIFS([1]日报透视!N:N,[1]日报透视!A:A,A47,[1]日报透视!B:B,B47) -> 0 | N47: =E47-L47 -> 12.855528 | O47: =VLOOKUP(B47,[1]门店ID对应关系!J:K,2,0) -> 自营 | Q47: =B47 -> 大坪店 | R47: =VLOOKUP(Q47,$B$4:$B$42,1,0) -> 大坪店 | T47: =VLOOKUP(B47,[1]房租水电人工成本!A:N,14,0)*V47*$W$1 -> 4.4444725 | U47: 0 | V47: =IFERROR(J47/SUMIF(B:B,B47,J:J),0.25) -> 0.012658228 | W47: =IFERROR(U47*V47,0.25) -> 0
A48: 京东 | B48: 百捷店 | C48: =SUMIFS([1]日报透视!E:E,[1]日报透视!A:A,A48,[1]日报透视!B:B,B48) -> 0 | D48: =SUMIFS([1]日报透视!F:F,[1]日报透视!A:A,A48,[1]日报透视!B:B,B48) -> 0 | E48: =SUMIFS([1]日报透视!G:G,[1]日报透视!A:A,A48,[1]日报透视!B:B,B48)-M48 -> 0 | F48: =IFERROR(G48/J48,0) -> 0 | G48: =SUMIFS([1]日报透视!I:I,[1]日报透视!A:A,A48,[1]日报透视!B:B,B48) -> 0 | H48: =SUMIFS([1]日报透视!J:J,[1]日报透视!A:A,A48,[1]日报透视!B:B,B48) -> 0 | I48: =SUMIFS([1]日报透视!K:K,[1]日报透视!A:A,A48,[1]日报透视!B:B,B48) -> 0 | J48: =SUMIFS([1]日报透视!L:L,[1]日报透视!A:A,A48,[1]日报透视!B:B,B48) -> 0 | K48: =IFERROR(I48/J48,0) -> 0 | L48: =T48 -> 0 | M48: =SUMIFS([1]日报透视!N:N,[1]日报透视!A:A,A48,[1]日报透视!B:B,B48) -> 0 | N48: =E48-L48 -> 0 | O48: =VLOOKUP(B48,[1]门店ID对应关系!J:K,2,0) -> 自营 | Q48: =B48 -> 百捷店 | R48: =VLOOKUP(Q48,$B$4:$B$42,1,0) -> 百捷店 | T48: =VLOOKUP(B48,[1]房租水电人工成本!A:N,14,0)*V48*$W$1 -> 0 | U48: 0 | V48: =IFERROR(J48/SUMIF(B:B,B48,J:J),0.25) -> 0 | W48: =IFERROR(U48*V48,0.25) -> 0
A49: 京东 | B49: 百丈店 | C49: =SUMIFS([1]日报透视!E:E,[1]日报透视!A:A,A49,[1]日报透视!B:B,B49) -> 0 | D49: =SUMIFS([1]日报透视!F:F,[1]日报透视!A:A,A49,[1]日报透视!B:B,B49) -> 0 | E49: =SUMIFS([1]日报透视!G:G,[1]日报透视!A:A,A49,[1]日报透视!B:B,B49)-M49 -> 0 | F49: =IFERROR(G49/J49,0) -> 0 | G49: =SUMIFS([1]日报透视!I:I,[1]日报透视!A:A,A49,[1]日报透视!B:B,B49) -> 0 | H49: =SUMIFS([1]日报透视!J:J,[1]日报透视!A:A,A49,[1]日报透视!B:B,B49) -> 0 | I49: =SUMIFS([1]日报透视!K:K,[1]日报透视!A:A,A49,[1]日报透视!B:B,B49) -> 0 | J49: =SUMIFS([1]日报透视!L:L,[1]日报透视!A:A,A49,[1]日报透视!B:B,B49) -> 0 | K49: =IFERROR(I49/J49,0) -> 0 | L49: =T49 -> 0 | M49: =SUMIFS([1]日报透视!N:N,[1]日报透视!A:A,A49,[1]日报透视!B:B,B49) -> 0 | N49: =E49-L49 -> 0 | O49: =VLOOKUP(B49,[1]门店ID对应关系!J:K,2,0) -> 自营 | Q49: =B49 -> 百丈店 | R49: =VLOOKUP(Q49,$B$4:$B$42,1,0) -> 百丈店 | T49: =VLOOKUP(B49,[1]房租水电人工成本!A:N,14,0)*V49*$W$1 -> 0 | U49: 0 | V49: =IFERROR(J49/SUMIF(B:B,B49,J:J),0.25) -> 0 | W49: =IFERROR(U49*V49,0.25) -> 0
A50: 京东 | B50: 成华店 | C50: =SUMIFS([1]日报透视!E:E,[1]日报透视!A:A,A50,[1]日报透视!B:B,B50) -> 0 | D50: =SUMIFS([1]日报透视!F:F,[1]日报透视!A:A,A50,[1]日报透视!B:B,B50) -> 0 | E50: =SUMIFS([1]日报透视!G:G,[1]日报透视!A:A,A50,[1]日报透视!B:B,B50)-M50 -> 0 | F50: =IFERROR(G50/J50,0) -> 0 | G50: =SUMIFS([1]日报透视!I:I,[1]日报透视!A:A,A50,[1]日报透视!B:B,B50) -> 0 | H50: =SUMIFS([1]日报透视!J:J,[1]日报透视!A:A,A50,[1]日报透视!B:B,B50) -> 0 | I50: =SUMIFS([1]日报透视!K:K,[1]日报透视!A:A,A50,[1]日报透视!B:B,B50) -> 0 | J50: =SUMIFS([1]日报透视!L:L,[1]日报透视!A:A,A50,[1]日报透视!B:B,B50) -> 0 | K50: =IFERROR(I50/J50,0) -> 0 | L50: =T50 -> 0 | M50: =SUMIFS([1]日报透视!N:N,[1]日报透视!A:A,A50,[1]日报透视!B:B,B50) -> 0 | N50: =E50-L50 -> 0 | O50: =VLOOKUP(B50,[1]门店ID对应关系!J:K,2,0) -> 自营 | Q50: =B50 -> 成华店 | R50: =VLOOKUP(Q50,$B$4:$B$42,1,0) -> 成华店 | T50: =VLOOKUP(B50,[1]房租水电人工成本!A:N,14,0)*V50*$W$1 -> 0 | U50: 0 | V50: =IFERROR(J50/SUMIF(B:B,B50,J:J),0.25) -> 0 | W50: =IFERROR(U50*V50,0.25) -> 0
A51: 京东 | B51: 东新店 | C51: =SUMIFS([1]日报透视!E:E,[1]日报透视!A:A,A51,[1]日报透视!B:B,B51) -> 0 | D51: =SUMIFS([1]日报透视!F:F,[1]日报透视!A:A,A51,[1]日报透视!B:B,B51) -> 0 | E51: =SUMIFS([1]日报透视!G:G,[1]日报透视!A:A,A51,[1]日报透视!B:B,B51)-M51 -> 0 | F51: =IFERROR(G51/J51,0) -> 0 | G51: =SUMIFS([1]日报透视!I:I,[1]日报透视!A:A,A51,[1]日报透视!B:B,B51) -> 0 | H51: =SUMIFS([1]日报透视!J:J,[1]日报透视!A:A,A51,[1]日报透视!B:B,B51) -> 0 | I51: =SUMIFS([1]日报透视!K:K,[1]日报透视!A:A,A51,[1]日报透视!B:B,B51) -> 0 | J51: =SUMIFS([1]日报透视!L:L,[1]日报透视!A:A,A51,[1]日报透视!B:B,B51) -> 0 | K51: =IFERROR(I51/J51,0) -> 0 | L51: =T51 -> 0 | M51: =SUMIFS([1]日报透视!N:N,[1]日报透视!A:A,A51,[1]日报透视!B:B,B51) -> 0 | N51: =E51-L51 -> 0 | O51: =VLOOKUP(B51,[1]门店ID对应关系!J:K,2,0) -> 自营 | Q51: =B51 -> 东新店 | R51: =VLOOKUP(Q51,$B$4:$B$42,1,0) -> 东新店 | T51: =VLOOKUP(B51,[1]房租水电人工成本!A:N,14,0)*V51*$W$1 -> 0 | U51: 0 | V51: =IFERROR(J51/SUMIF(B:B,B51,J:J),0.25) -> 0 | W51: =IFERROR(U51*V51,0.25) -> 0
A52: 京东 | B52: 凤城二路店 | C52: =SUMIFS([1]日报透视!E:E,[1]日报透视!A:A,A52,[1]日报透视!B:B,B52) -> 31.45 | D52: =SUMIFS([1]日报透视!F:F,[1]日报透视!A:A,A52,[1]日报透视!B:B,B52) -> 9 | E52: =SUMIFS([1]日报透视!G:G,[1]日报透视!A:A,A52,[1]日报透视!B:B,B52)-M52 -> 22.45 | F52: =IFERROR(G52/J52,0) -> 1.8 | G52: =SUMIFS([1]日报透视!I:I,[1]日报透视!A:A,A52,[1]日报透视!B:B,B52) -> 1.8 | H52: =SUMIFS([1]日报透视!J:J,[1]日报透视!A:A,A52,[1]日报透视!B:B,B52) -> 1.75 | I52: =SUMIFS([1]日报透视!K:K,[1]日报透视!A:A,A52,[1]日报透视!B:B,B52) -> 0.178 | J52: =SUMIFS([1]日报透视!L:L,[1]日报透视!A:A,A52,[1]日报透视!B:B,B52) -> 1 | K52: =IFERROR(I52/J52,0) -> 0.178 | L52: =T52 -> 4.3632918 | M52: =SUMIFS([1]日报透视!N:N,[1]日报透视!A:A,A52,[1]日报透视!B:B,B52) -> 0 | N52: =E52-L52 -> 18.086708 | O52: =VLOOKUP(B52,[1]门店ID对应关系!J:K,2,0) -> 自营 | Q52: =B52 -> 凤城二路店 | R52: =VLOOKUP(Q52,$B$4:$B$42,1,0) -> 凤城二路店 | T52: =VLOOKUP(B52,[1]房租水电人工成本!A:N,14,0)*V52*$W$1 -> 4.3632918 | U52: 0 | V52: =IFERROR(J52/SUMIF(B:B,B52,J:J),0.25) -> 0.0068493151 | W52: =IFERROR(U52*V52,0.25) -> 0
A53: 京东 | B53: 高新店 | C53: =SUMIFS([1]日报透视!E:E,[1]日报透视!A:A,A53,[1]日报透视!B:B,B53) -> 0 | D53: =SUMIFS([1]日报透视!F:F,[1]日报透视!A:A,A53,[1]日报透视!B:B,B53) -> 0 | E53: =SUMIFS([1]日报透视!G:G,[1]日报透视!A:A,A53,[1]日报透视!B:B,B53)-M53 -> 0 | F53: =IFERROR(G53/J53,0) -> 0 | G53: =SUMIFS([1]日报透视!I:I,[1]日报透视!A:A,A53,[1]日报透视!B:B,B53) -> 0 | H53: =SUMIFS([1]日报透视!J:J,[1]日报透视!A:A,A53,[1]日报透视!B:B,B53) -> 0 | I53: =SUMIFS([1]日报透视!K:K,[1]日报透视!A:A,A53,[1]日报透视!B:B,B53) -> 0 | J53: =SUMIFS([1]日报透视!L:L,[1]日报透视!A:A,A53,[1]日报透视!B:B,B53) -> 0 | K53: =IFERROR(I53/J53,0) -> 0 | L53: =T53 -> 0 | M53: =SUMIFS([1]日报透视!N:N,[1]日报透视!A:A,A53,[1]日报透视!B:B,B53) -> 0 | N53: =E53-L53 -> 0 | O53: =VLOOKUP(B53,[1]门店ID对应关系!J:K,2,0) -> 自营 | Q53: =B53 -> 高新店 | R53: =VLOOKUP(Q53,$B$4:$B$42,1,0) -> 高新店 | T53: =VLOOKUP(B53,[1]房租水电人工成本!A:N,14,0)*V53*$W$1 -> 0 | U53: 0 | V53: =IFERROR(J53/SUMIF(B:B,B53,J:J),0.25) -> 0 | W53: =IFERROR(U53*V53,0.25) -> 0
A54: 京东 | B54: 鼓楼店 | C54: =SUMIFS([1]日报透视!E:E,[1]日报透视!A:A,A54,[1]日报透视!B:B,B54) -> 0 | D54: =SUMIFS([1]日报透视!F:F,[1]日报透视!A:A,A54,[1]日报透视!B:B,B54) -> 0 | E54: =SUMIFS([1]日报透视!G:G,[1]日报透视!A:A,A54,[1]日报透视!B:B,B54)-M54 -> 0 | F54: =IFERROR(G54/J54,0) -> 0 | G54: =SUMIFS([1]日报透视!I:I,[1]日报透视!A:A,A54,[1]日报透视!B:B,B54) -> 0 | H54: =SUMIFS([1]日报透视!J:J,[1]日报透视!A:A,A54,[1]日报透视!B:B,B54) -> 0 | I54: =SUMIFS([1]日报透视!K:K,[1]日报透视!A:A,A54,[1]日报透视!B:B,B54) -> 0 | J54: =SUMIFS([1]日报透视!L:L,[1]日报透视!A:A,A54,[1]日报透视!B:B,B54) -> 0 | K54: =IFERROR(I54/J54,0) -> 0 | L54: =T54 -> 0 | M54: =SUMIFS([1]日报透视!N:N,[1]日报透视!A:A,A54,[1]日报透视!B:B,B54) -> 0 | N54: =E54-L54 -> 0 | O54: =VLOOKUP(B54,[1]门店ID对应关系!J:K,2,0) -> 自营 | Q54: =B54 -> 鼓楼店 | R54: =VLOOKUP(Q54,$B$4:$B$42,1,0) -> 鼓楼店 | T54: =VLOOKUP(B54,[1]房租水电人工成本!A:N,14,0)*V54*$W$1 -> 0 | U54: 0 | V54: =IFERROR(J54/SUMIF(B:B,B54,J:J),0.25) -> 0 | W54: =IFERROR(U54*V54,0.25) -> 0
A55: 京东 | B55: 观桥店 | C55: =SUMIFS([1]日报透视!E:E,[1]日报透视!A:A,A55,[1]日报透视!B:B,B55) -> 64.7 | D55: =SUMIFS([1]日报透视!F:F,[1]日报透视!A:A,A55,[1]日报透视!B:B,B55) -> 37.8 | E55: =SUMIFS([1]日报透视!G:G,[1]日报透视!A:A,A55,[1]日报透视!B:B,B55)-M55 -> 26.9 | F55: =IFERROR(G55/J55,0) -> 1.8 | G55: =SUMIFS([1]日报透视!I:I,[1]日报透视!A:A,A55,[1]日报透视!B:B,B55) -> 1.8 | H55: =SUMIFS([1]日报透视!J:J,[1]日报透视!A:A,A55,[1]日报透视!B:B,B55) -> 3.5 | I55: =SUMIFS([1]日报透视!K:K,[1]日报透视!A:A,A55,[1]日报透视!B:B,B55) -> 0.562 | J55: =SUMIFS([1]日报透视!L:L,[1]日报透视!A:A,A55,[1]日报透视!B:B,B55) -> 1 | K55: =IFERROR(I55/J55,0) -> 0.562 | L55: =T55 -> 3.2016712 | M55: =SUMIFS([1]日报透视!N:N,[1]日报透视!A:A,A55,[1]日报透视!B:B,B55) -> 0 | N55: =E55-L55 -> 23.698329 | O55: =VLOOKUP(B55,[1]门店ID对应关系!J:K,2,0) -> 自营 | Q55: =B55 -> 观桥店 | R55: =VLOOKUP(Q55,$B$4:$B$42,1,0) -> 观桥店 | T55: =VLOOKUP(B55,[1]房租水电人工成本!A:N,14,0)*V55*$W$1 -> 3.2016712 | U55: 0 | V55: =IFERROR(J55/SUMIF(B:B,B55,J:J),0.25) -> 0.012195122 | W55: =IFERROR(U55*V55,0.25) -> 0
... A81: 京东 | B81: 首南店 | C81: =SUMIFS([1]日报透视!E:E,[1]日报透视!A:A,A81,[1]日报透视!B:B,B81) -> 39.05 | D81: =SUMIFS([1]日报透视!F:F,[1]日报透视!A:A,A81,[1]日报透视!B:B,B81) -> 12.72 | E81: =SUMIFS([1]日报透视!G:G,[1]日报透视!A:A,A81,[1]日报透视!B:B,B81)-M81 -> 26.33 | F81: =IFERROR(G81/J81,0) -> 1.8 | G81: =SUMIFS([1]日报透视!I:I,[1]日报透视!A:A,A81,[1]日报透视!B:B,B81) -> 1.8 | H81: =SUMIFS([1]日报透视!J:J,[1]日报透视!A:A,A81,[1]日报透视!B:B,B81) -> 2.15 | I81: =SUMIFS([1]日报透视!K:K,[1]日报透视!A:A,A81,[1]日报透视!B:B,B81) -> 14.415 | J81: =SUMIFS([1]日报透视!L:L,[1]日报透视!A:A,A81,[1]日报透视!B:B,B81) -> 1 | K81: =IFERROR(I81/J81,0) -> 14.415 | L81: =T81 -> 3.6748188 | M81: =SUMIFS([1]日报透视!N:N,[1]日报透视!A:A,A81,[1]日报透视!B:B,B81) -> 0 | N81: =E81-L81 -> 22.655181 | O81: =VLOOKUP(B81,[1]门店ID对应关系!J:K,2,0) -> 自营 | Q81: =B81 -> 首南店 | R81: =VLOOKUP(Q81,$B$4:$B$42,1,0) -> 首南店 | T81: =VLOOKUP(B81,[1]房租水电人工成本!A:N,14,0)*V81*$W$1 -> 3.6748188 | U81: 0 | V81: =IFERROR(J81/SUMIF(B:B,B81,J:J),0.25) -> 0.0067567568 | W81: =IFERROR(U81*V81,0.25) -> 0
A82: 美团 | B82: 海口店 | C82: =SUMIFS([1]日报透视!E:E,[1]日报透视!A:A,A82,[1]日报透视!B:B,B82) -> 2785.4551 | D82: =SUMIFS([1]日报透视!F:F,[1]日报透视!A:A,A82,[1]日报透视!B:B,B82) -> 1973.1733 | E82: =SUMIFS([1]日报透视!G:G,[1]日报透视!A:A,A82,[1]日报透视!B:B,B82)-M82 -> 590.13178 | F82: =IFERROR(G82/J82,0) -> 6.8271712 | G82: =SUMIFS([1]日报透视!I:I,[1]日报透视!A:A,A82,[1]日报透视!B:B,B82) -> 832.91489 | H82: =SUMIFS([1]日报透视!J:J,[1]日报透视!A:A,A82,[1]日报透视!B:B,B82) -> 269.97 | I82: =SUMIFS([1]日报透视!K:K,[1]日报透视!A:A,A82,[1]日报透视!B:B,B82) -> 584.398 | J82: =SUMIFS([1]日报透视!L:L,[1]日报透视!A:A,A82,[1]日报透视!B:B,B82) -> 122 | K82: =IFERROR(I82/J82,0) -> 4.7901475 | L82: =T82 -> 534.30657 | M82: =SUMIFS([1]日报透视!M:M,[1]日报透视!A:A,A82,[1]日报透视!B:B,B82) -> 222.15 | N82: =E82-L82 -> 55.825206 | O82: =VLOOKUP(B82,[1]门店ID对应关系!J:K,2,0) -> 加盟 | P82: =SUM($N$82:$N$120) -> 827.11267 | Q82: =B82 -> 海口店 | R82: =VLOOKUP(Q82,$B$4:$B$42,1,0) -> 海口店 | T82: =VLOOKUP(B82,[1]房租水电人工成本!A:N,14,0)*V82*$W$1 -> 534.30657 | U82: =-SUMIFS([1]美团推广费!J:J,[1]美团推广费!C:C,"推广订单扣款",[1]美团推广费!H:H,B82,[1]美团推广费!I:I,$U$1) -> 222.15 | V82: =IFERROR(J82/SUMIF(B:B,B82,J:J),0.25) -> 0.89051095 | W82: =IFERROR(U82*V82,0.25) -> 197.82701
A83: 美团 | B83: 首南店 | C83: =SUMIFS([1]日报透视!E:E,[1]日报透视!A:A,A83,[1]日报透视!B:B,B83) -> 2000.5428 | D83: =SUMIFS([1]日报透视!F:F,[1]日报透视!A:A,A83,[1]日报透视!B:B,B83) -> 1292.8401 | E83: =SUMIFS([1]日报透视!G:G,[1]日报透视!A:A,A83,[1]日报透视!B:B,B83)-M83 -> 562.39271 | F83: =IFERROR(G83/J83,0) -> 7.904142 | G83: =SUMIFS([1]日报透视!I:I,[1]日报透视!A:A,A83,[1]日报透视!B:B,B83) -> 624.42722 | H83: =SUMIFS([1]日报透视!J:J,[1]日报透视!A:A,A83,[1]日报透视!B:B,B83) -> 191.97 | I83: =SUMIFS([1]日报透视!K:K,[1]日报透视!A:A,A83,[1]日报透视!B:B,B83) -> 364.911 | J83: =SUMIFS([1]日报透视!L:L,[1]日报透视!A:A,A83,[1]日报透视!B:B,B83) -> 79 | K83: =IFERROR(I83/J83,0) -> 4.6191266 | L83: =T83 -> 290.31069 | M83: =SUMIFS([1]日报透视!M:M,[1]日报透视!A:A,A83,[1]日报透视!B:B,B83) -> 145.31 | N83: =E83-L83 -> 272.08203 | O83: =VLOOKUP(B83,[1]门店ID对应关系!J:K,2,0) -> 自营 | Q83: =B83 -> 首南店 | R83: =VLOOKUP(Q83,$B$4:$B$42,1,0) -> 首南店 | T83: =VLOOKUP(B83,[1]房租水电人工成本!A:N,14,0)*V83*$W$1 -> 290.31069 | U83: =-SUMIFS([1]美团推广费!J:J,[1]美团推广费!C:C,"推广订单扣款",[1]美团推广费!H:H,B83,[1]美团推广费!I:I,$U$1) -> 145.31 | V83: =IFERROR(J83/SUMIF(B:B,B83,J:J),0.25) -> 0.53378378 | W83: =IFERROR(U83*V83,0.25) -> 77.564122
A84: 美团 | B84: 济南店 | C84: =SUMIFS([1]日报透视!E:E,[1]日报透视!A:A,A84,[1]日报透视!B:B,B84) -> 1876.2578 | D84: =SUMIFS([1]日报透视!F:F,[1]日报透视!A:A,A84,[1]日报透视!B:B,B84) -> 1152.7554 | E84: =SUMIFS([1]日报透视!G:G,[1]日报透视!A:A,A84,[1]日报透视!B:B,B84)-M84 -> 602.25237 | F84: =IFERROR(G84/J84,0) -> 7.5924104 | G84: =SUMIFS([1]日报透视!I:I,[1]日报透视!A:A,A84,[1]日报透视!B:B,B84) -> 447.95221 | H84: =SUMIFS([1]日报透视!J:J,[1]日报透视!A:A,A84,[1]日报透视!B:B,B84) -> 175.04 | I84: =SUMIFS([1]日报透视!K:K,[1]日报透视!A:A,A84,[1]日报透视!B:B,B84) -> 243.966 | J84: =SUMIFS([1]日报透视!L:L,[1]日报透视!A:A,A84,[1]日报透视!B:B,B84) -> 59 | K84: =IFERROR(I84/J84,0) -> 4.1350169 | L84: =T84 -> 299.99526 | M84: =SUMIFS([1]日报透视!M:M,[1]日报透视!A:A,A84,[1]日报透视!B:B,B84) -> 121.25 | N84: =E84-L84 -> 302.2571 | O84: =VLOOKUP(B84,[1]门店ID对应关系!J:K,2,0) -> 自营 | Q84: =B84 -> 济南店 | R84: =VLOOKUP(Q84,$B$4:$B$42,1,0) -> 济南店 | T84: =VLOOKUP(B84,[1]房租水电人工成本!A:N,14,0)*V84*$W$1 -> 299.99526 | U84: =-SUMIFS([1]美团推广费!J:J,[1]美团推广费!C:C,"推广订单扣款",[1]美团推广费!H:H,B84,[1]美团推广费!I:I,$U$1) -> 121.25 | V84: =IFERROR(J84/SUMIF(B:B,B84,J:J),0.25) -> 0.46456693 | W84: =IFERROR(U84*V84,0.25) -> 56.32874
A85: 美团 | B85: 官渡店 | C85: =SUMIFS([1]日报透视!E:E,[1]日报透视!A:A,A85,[1]日报透视!B:B,B85) -> 2316.3779 | D85: =SUMIFS([1]日报透视!F:F,[1]日报透视!A:A,A85,[1]日报透视!B:B,B85) -> 1516.438 | E85: =SUMIFS([1]日报透视!G:G,[1]日报透视!A:A,A85,[1]日报透视!B:B,B85)-M85 -> 693.52989 | F85: =IFERROR(G85/J85,0) -> 6.174729 | G85: =SUMIFS([1]日报透视!I:I,[1]日报透视!A:A,A85,[1]日报透视!B:B,B85) -> 407.53211 | H85: =SUMIFS([1]日报透视!J:J,[1]日报透视!A:A,A85,[1]日报透视!B:B,B85) -> 205.18 | I85: =SUMIFS([1]日报透视!K:K,[1]日报透视!A:A,A85,[1]日报透视!B:B,B85) -> 196.03 | J85: =SUMIFS([1]日报透视!L:L,[1]日报透视!A:A,A85,[1]日报透视!B:B,B85) -> 66 | K85: =IFERROR(I85/J85,0) -> 2.9701515 | L85: =T85 -> 278.43575 | M85: =SUMIFS([1]日报透视!M:M,[1]日报透视!A:A,A85,[1]日报透视!B:B,B85) -> 106.41 | N85: =E85-L85 -> 415.09414 | O85: =VLOOKUP(B85,[1]门店ID对应关系!J:K,2,0) -> 自营 | Q85: =B85 -> 官渡店 | R85: =VLOOKUP(Q85,$B$4:$B$42,1,0) -> 官渡店 | T85: =VLOOKUP(B85,[1]房租水电人工成本!A:N,14,0)*V85*$W$1 -> 278.43575 | U85: =-SUMIFS([1]美团推广费!J:J,[1]美团推广费!C:C,"推广订单扣款",[1]美团推广费!H:H,B85,[1]美团推广费!I:I,$U$1) -> 106.41 | V85: =IFERROR(J85/SUMIF(B:B,B85,J:J),0.25) -> 0.6875 | W85: =IFERROR(U85*V85,0.25) -> 73.156875
A86: 美团 | B86: 长沙店 | C86: =SUMIFS([1]日报透视!E:E,[1]日报透视!A:A,A86,[1]日报透视!B:B,B86) -> 1859.5161 | D86: =SUMIFS([1]日报透视!F:F,[1]日报透视!A:A,A86,[1]日报透视!B:B,B86) -> 1304.3742 | E86: =SUMIFS([1]日报透视!G:G,[1]日报透视!A:A,A86,[1]日报透视!B:B,B86)-M86 -> 470.74193 | F86: =IFERROR(G86/J86,0) -> 7.2284057 | G86: =SUMIFS([1]日报透视!I:I,[1]日报透视!A:A,A86,[1]日报透视!B:B,B86) -> 390.33391 | H86: =SUMIFS([1]日报透视!J:J,[1]日报透视!A:A,A86,[1]日报透视!B:B,B86) -> 169.49 | I86: =SUMIFS([1]日报透视!K:K,[1]日报透视!A:A,A86,[1]日报透视!B:B,B86) -> 233.055 | J86: =SUMIFS([1]日报透视!L:L,[1]日报透视!A:A,A86,[1]日报透视!B:B,B86) -> 54 | K86: =IFERROR(I86/J86,0) -> 4.3158333 | L86: =T86 -> 187.5 | M86: =SUMIFS([1]日报透视!M:M,[1]日报透视!A:A,A86,[1]日报透视!B:B,B86) -> 84.4 | N86: =E86-L86 -> 283.24193 | O86: =VLOOKUP(B86,[1]门店ID对应关系!J:K,2,0) -> （加盟） | Q86: =B86 -> 长沙店 | R86: =VLOOKUP(Q86,$B$4:$B$42,1,0) -> 长沙店 | T86: =VLOOKUP(B86,[1]房租水电人工成本!A:N,14,0)*V86*$W$1 -> 187.5 | U86: =-SUMIFS([1]美团推广费!J:J,[1]美团推广费!C:C,"推广订单扣款",[1]美团推广费!H:H,B86,[1]美团推广费!I:I,$U$1) -> 84.4 | V86: =IFERROR(J86/SUMIF(B:B,B86,J:J),0.25) -> 0.5625 | W86: =IFERROR(U86*V86,0.25) -> 47.475
A87: 美团 | B87: 余杭店 | C87: =SUMIFS([1]日报透视!E:E,[1]日报透视!A:A,A87,[1]日报透视!B:B,B87) -> 1356.1921 | D87: =SUMIFS([1]日报透视!F:F,[1]日报透视!A:A,A87,[1]日报透视!B:B,B87) -> 911.9225 | E87: =SUMIFS([1]日报透视!G:G,[1]日报透视!A:A,A87,[1]日报透视!B:B,B87)-M87 -> 299.26964 | F87: =IFERROR(G87/J87,0) -> 7.8740345 | G87: =SUMIFS([1]日报透视!I:I,[1]日报透视!A:A,A87,[1]日报透视!B:B,B87) -> 425.19786 | H87: =SUMIFS([1]日报透视!J:J,[1]日报透视!A:A,A87,[1]日报透视!B:B,B87) -> 130.15 | I87: =SUMIFS([1]日报透视!K:K,[1]日报透视!A:A,A87,[1]日报透视!B:B,B87) -> 225.802 | J87: =SUMIFS([1]日报透视!L:L,[1]日报透视!A:A,A87,[1]日报透视!B:B,B87) -> 54 | K87: =IFERROR(I87/J87,0) -> 4.1815185 | L87: =T87 -> 184.3123 | M87: =SUMIFS([1]日报透视!M:M,[1]日报透视!A:A,A87,[1]日报透视!B:B,B87) -> 145 | N87: =E87-L87 -> 114.95734 | O87: =VLOOKUP(B87,[1]门店ID对应关系!J:K,2,0) -> 自营 | Q87: =B87 -> 余杭店 | R87: =VLOOKUP(Q87,$B$4:$B$42,1,0) -> 余杭店 | T87: =VLOOKUP(B87,[1]房租水电人工成本!A:N,14,0)*V87*$W$1 -> 184.3123 | U87: =-SUMIFS([1]美团推广费!J:J,[1]美团推广费!C:C,"推广订单扣款",[1]美团推广费!H:H,B87,[1]美团推广费!I:I,$U$1) -> 145 | V87: =IFERROR(J87/SUMIF(B:B,B87,J:J),0.25) -> 0.4 | W87: =IFERROR(U87*V87,0.25) -> 58
A88: 美团 | B88: 文昌店 | C88: =SUMIFS([1]日报透视!E:E,[1]日报透视!A:A,A88,[1]日报透视!B:B,B88) -> 738.79614 | D88: =SUMIFS([1]日报透视!F:F,[1]日报透视!A:A,A88,[1]日报透视!B:B,B88) -> 487.351 | E88: =SUMIFS([1]日报透视!G:G,[1]日报透视!A:A,A88,[1]日报透视!B:B,B88)-M88 -> 130.90514 | F88: =IFERROR(G88/J88,0) -> 5.4295516 | G88: =SUMIFS([1]日报透视!I:I,[1]日报透视!A:A,A88,[1]日报透视!B:B,B88) -> 195.46386 | H88: =SUMIFS([1]日报透视!J:J,[1]日报透视!A:A,A88,[1]日报透视!B:B,B88) -> 67.97 | I88: =SUMIFS([1]日报透视!K:K,[1]日报透视!A:A,A88,[1]日报透视!B:B,B88) -> 96.614 | J88: =SUMIFS([1]日报透视!L:L,[1]日报透视!A:A,A88,[1]日报透视!B:B,B88) -> 36 | K88: =IFERROR(I88/J88,0) -> 2.6837222 | L88: =T88 -> 288.45164 | M88: =SUMIFS([1]日报透视!M:M,[1]日报透视!A:A,A88,[1]日报透视!B:B,B88) -> 120.54 | N88: =E88-L88 -> -157.54649 | O88: =VLOOKUP(B88,[1]门店ID对应关系!J:K,2,0) -> 自营 | Q88: =B88 -> 文昌店 | R88: =VLOOKUP(Q88,$B$4:$B$42,1,0) -> 文昌店 | T88: =VLOOKUP(B88,[1]房租水电人工成本!A:N,14,0)*V88*$W$1 -> 288.45164 | U88: =-SUMIFS([1]美团推广费!J:J,[1]美团推广费!C:C,"推广订单扣款",[1]美团推广费!H:H,B88,[1]美团推广费!I:I,$U$1) -> 120.54 | V88: =IFERROR(J88/SUMIF(B:B,B88,J:J),0.25) -> 0.8372093 | W88: =IFERROR(U88*V88,0.25) -> 100.91721
A89: 美团 | B89: 黄雁村店 | C89: =SUMIFS([1]日报透视!E:E,[1]日报透视!A:A,A89,[1]日报透视!B:B,B89) -> 2179.215 | D89: =SUMIFS([1]日报透视!F:F,[1]日报透视!A:A,A89,[1]日报透视!B:B,B89) -> 1460.9758 | E89: =SUMIFS([1]日报透视!G:G,[1]日报透视!A:A,A89,[1]日报透视!B:B,B89)-M89 -> 593.2592 | F89: =IFERROR(G89/J89,0) -> 6.5861801 | G89: =SUMIFS([1]日报透视!I:I,[1]日报透视!A:A,A89,[1]日报透视!B:B,B89) -> 474.20496 | H89: =SUMIFS([1]日报透视!J:J,[1]日报透视!A:A,A89,[1]日报透视!B:B,B89) -> 171.64 | I89: =SUMIFS([1]日报透视!K:K,[1]日报透视!A:A,A89,[1]日报透视!B:B,B89) -> 275.376 | J89: =SUMIFS([1]日报透视!L:L,[1]日报透视!A:A,A89,[1]日报透视!B:B,B89) -> 72 | K89: =IFERROR(I89/J89,0) -> 3.8246667 | L89: =T89 -> 260.20304 | M89: =SUMIFS([1]日报透视!M:M,[1]日报透视!A:A,A89,[1]日报透视!B:B,B89) -> 124.98 | N89: =E89-L89 -> 333.05616 | O89: =VLOOKUP(B89,[1]门店ID对应关系!J:K,2,0) -> 自营 | Q89: =B89 -> 黄雁村店 | R89: =VLOOKUP(Q89,$B$4:$B$42,1,0) -> 黄雁村店 | T89: =VLOOKUP(B89,[1]房租水电人工成本!A:N,14,0)*V89*$W$1 -> 260.20304 | U89: =-SUMIFS([1]美团推广费!J:J,[1]美团推广费!C:C,"推广订单扣款",[1]美团推广费!H:H,B89,[1]美团推广费!I:I,$U$1) -> 124.98 | V89: =IFERROR(J89/SUMIF(B:B,B89,J:J),0.25) -> 0.49315068 | W89: =IFERROR(U89*V89,0.25) -> 61.633973
A90: 美团 | B90: 鼓楼店 | C90: =SUMIFS([1]日报透视!E:E,[1]日报透视!A:A,A90,[1]日报透视!B:B,B90) -> 2652.1638 | D90: =SUMIFS([1]日报透视!F:F,[1]日报透视!A:A,A90,[1]日报透视!B:B,B90) -> 1952.9343 | E90: =SUMIFS([1]日报透视!G:G,[1]日报透视!A:A,A90,[1]日报透视!B:B,B90)-M90 -> 499.22951 | F90: =IFERROR(G90/J90,0) -> 6.5554635 | G90: =SUMIFS([1]日报透视!I:I,[1]日报透视!A:A,A90,[1]日报透视!B:B,B90) -> 511.32616 | H90: =SUMIFS([1]日报透视!J:J,[1]日报透视!A:A,A90,[1]日报透视!B:B,B90) -> 232.81 | I90: =SUMIFS([1]日报透视!K:K,[1]日报透视!A:A,A90,[1]日报透视!B:B,B90) -> 342.156 | J90: =SUMIFS([1]日报透视!L:L,[1]日报透视!A:A,A90,[1]日报透视!B:B,B90) -> 78 | K90: =IFERROR(I90/J90,0) -> 4.3866154 | L90: =T90 -> 256.23012 | M90: =SUMIFS([1]日报透视!M:M,[1]日报透视!A:A,A90,[1]日报透视!B:B,B90) -> 200 | N90: =E90-L90 -> 242.99939 | O90: =VLOOKUP(B90,[1]门店ID对应关系!J:K,2,0) -> 自营 | Q90: =B90 -> 鼓楼店 | R90: =VLOOKUP(Q90,$B$4:$B$42,1,0) -> 鼓楼店 | T90: =VLOOKUP(B90,[1]房租水电人工成本!A:N,14,0)*V90*$W$1 -> 256.23012 | U90: =-SUMIFS([1]美团推广费!J:J,[1]美团推广费!C:C,"推广订单扣款",[1]美团推广费!H:H,B90,[1]美团推广费!I:I,$U$1) -> 200 | V90: =IFERROR(J90/SUMIF(B:B,B90,J:J),0.25) -> 0.54166667 | W90: =IFERROR(U90*V90,0.25) -> 108.33333
...
